<?xml version="1.0" encoding="UTF-8"?>
<!-- Generated by org.testng.reporters.JUnitReportReporter -->
<testsuite hostname="LenovoT430AAM" name="FA_Test.Expense_Tracker_App_TestNG_Test" tests="9" failures="1" timestamp="10 Jun 2019 14:11:24 GMT" time="18.045" errors="0">
  <testcase name="Verify_Application_Title" time="0.010" classname="FA_Test.Expense_Tracker_App_TestNG_Test"/>
  <testcase name="New_Expense_Bug_workaround" time="4.055" classname="FA_Test.Expense_Tracker_App_TestNG_Test"/>
  <testcase name="New_Expense_Bug_catch" time="1.696" classname="FA_Test.Expense_Tracker_App_TestNG_Test">
    <failure type="java.lang.AssertionError" message="expected:&lt;Add Expense&gt; but was:&lt;List Expenses:&gt;">
      <![CDATA[java.lang.AssertionError: expected:<Add Expense> but was:<List Expenses:>
	at org.testng.AssertJUnit.assertEquals(AssertJUnit.java:101)
	at org.testng.AssertJUnit.assertEquals(AssertJUnit.java:108)
	at FA_Test.Expense_Tracker_App_TestNG_Test.New_Expense_Bug_catch(Expense_Tracker_App_TestNG_Test.java:302)
	at sun.reflect.NativeMethodAccessorImpl.invoke0(Native Method)
	at sun.reflect.NativeMethodAccessorImpl.invoke(Unknown Source)
	at sun.reflect.DelegatingMethodAccessorImpl.invoke(Unknown Source)
	at java.lang.reflect.Method.invoke(Unknown Source)
	at org.testng.internal.MethodInvocationHelper.invokeMethod(MethodInvocationHelper.java:85)
	at org.testng.internal.Invoker.invokeMethod(Invoker.java:639)
	at org.testng.internal.Invoker.invokeTestMethod(Invoker.java:816)
	at org.testng.internal.Invoker.invokeTestMethods(Invoker.java:1124)
	at org.testng.internal.TestMethodWorker.invokeTestMethods(TestMethodWorker.java:125)
	at org.testng.internal.TestMethodWorker.run(TestMethodWorker.java:108)
	at org.testng.TestRunner.privateRun(TestRunner.java:774)
	at org.testng.TestRunner.run(TestRunner.java:624)
	at org.testng.SuiteRunner.runTest(SuiteRunner.java:359)
	at org.testng.SuiteRunner.runSequentially(SuiteRunner.java:354)
	at org.testng.SuiteRunner.privateRun(SuiteRunner.java:312)
	at org.testng.SuiteRunner.run(SuiteRunner.java:261)
	at org.testng.SuiteRunnerWorker.runSuite(SuiteRunnerWorker.java:52)
	at org.testng.SuiteRunnerWorker.run(SuiteRunnerWorker.java:86)
	at org.testng.TestNG.runSuitesSequentially(TestNG.java:1215)
	at org.testng.TestNG.runSuitesLocally(TestNG.java:1140)
	at org.testng.TestNG.run(TestNG.java:1048)
	at org.testng.remote.AbstractRemoteTestNG.run(AbstractRemoteTestNG.java:132)
	at org.testng.remote.RemoteTestNG.initAndRun(RemoteTestNG.java:230)
	at org.testng.remote.RemoteTestNG.main(RemoteTestNG.java:76)
]]>
    </failure>
  </testcase> <!-- New_Expense_Bug_catch -->
  <testcase name="Show_Stats" time="2.553" classname="FA_Test.Expense_Tracker_App_TestNG_Test"/>
  <testcase name="Verify_Page_Title" time="0.562" classname="FA_Test.Expense_Tracker_App_TestNG_Test"/>
  <testcase name="Verify_Url" time="0.014" classname="FA_Test.Expense_Tracker_App_TestNG_Test"/>
  <testcase name="New_User_Register" time="1.292" classname="FA_Test.Expense_Tracker_App_TestNG_Test"/>
  <testcase name="New_Category" time="5.612" classname="FA_Test.Expense_Tracker_App_TestNG_Test"/>
  <testcase name="Edit_Account" time="2.251" classname="FA_Test.Expense_Tracker_App_TestNG_Test"/>
</testsuite> <!-- FA_Test.Expense_Tracker_App_TestNG_Test -->
